Jun 17 05:03:51 master0 astra-scheduler[38651]: I0617 05:03:51.817295   38651 schedule_one.go:83] "About to try and schedule pod" pod="astra-eval/eval-office-agent-654bd9764-bqnth"
Jun 17 05:03:51 master0 astra-scheduler[38651]: I0617 05:03:51.817300   38651 schedule_one.go:99] "Attempting to schedule pod" pod="astra-eval/eval-office-agent-654bd9764-bqnth"
Jun 17 05:03:51 master0 astra-scheduler[38651]: I0617 05:03:51.820948   38651 batch.go:90] "OpportunisticBatch no node hint available for pod" profile="astra-scheduler" pod="astra-eval/eval-office-agent-654bd9764-bqnth" cycleCount=12
Jun 17 05:03:51 master0 astra-scheduler[38651]: I0617 05:03:51.828208   38651 batch.go:118] "OpportunisticBatch set cycle state" pod="astra-eval/eval-office-agent-654bd9764-bqnth" profile="astra-scheduler" cycleCount=12 hintedNode="" chosenNode="master0"
Jun 17 05:03:51 master0 astra-scheduler[38651]: I0617 05:03:51.828233   38651 batch.go:168] "OpportunisticBatch found unusable state" pod="astra-eval/eval-office-agent-654bd9764-bqnth" profile="astra-scheduler" cycleCount=12 reason="pod_not_batchable"
Jun 17 05:03:51 master0 astra-scheduler[38651]: I0617 05:03:51.838316   38651 schedule_one.go:83] "About to try and schedule pod" pod="astra-eval/eval-live-moderation-5ff9cd648-7qs8p"
Jun 17 05:03:51 master0 astra-scheduler[38651]: I0617 05:03:51.838334   38651 schedule_one.go:99] "Attempting to schedule pod" pod="astra-eval/eval-live-moderation-5ff9cd648-7qs8p"
Jun 17 05:03:51 master0 astra-scheduler[38651]: I0617 05:03:51.838388   38651 pod_binding.go:51] "Attempting to bind pod to node" pod="astra-eval/eval-office-agent-654bd9764-bqnth" node="master0"
Jun 17 05:03:51 master0 astra-scheduler[38651]: I0617 05:03:51.842564   38651 batch.go:90] "OpportunisticBatch no node hint available for pod" profile="astra-scheduler" pod="astra-eval/eval-live-moderation-5ff9cd648-7qs8p" cycleCount=13
Jun 17 05:03:51 master0 astra-scheduler[38651]: I0617 05:03:51.844707   38651 schedule_one.go:337] "Successfully bound pod to node" pod="astra-eval/eval-office-agent-654bd9764-bqnth" node="master0" evaluatedNodes=4 feasibleNodes=4
Jun 17 05:03:51 master0 astra-scheduler[38651]: I0617 05:03:51.846207   38651 eventhandlers.go:391] "Add event for scheduled pod" pod="astra-eval/eval-office-agent-654bd9764-bqnth"
Jun 17 05:03:51 master0 astra-scheduler[38651]: I0617 05:03:51.846263   38651 eventhandlers.go:352] "Delete event for unscheduled pod" pod="astra-eval/eval-office-agent-654bd9764-bqnth"
Jun 17 05:03:51 master0 astra-scheduler[38651]: I0617 05:03:51.851611   38651 batch.go:118] "OpportunisticBatch set cycle state" pod="astra-eval/eval-live-moderation-5ff9cd648-7qs8p" profile="astra-scheduler" cycleCount=13 hintedNode="" chosenNode="worker1"
Jun 17 05:03:51 master0 astra-scheduler[38651]: I0617 05:03:51.851626   38651 batch.go:168] "OpportunisticBatch found unusable state" pod="astra-eval/eval-live-moderation-5ff9cd648-7qs8p" profile="astra-scheduler" cycleCount=13 reason="pod_not_batchable"
Jun 17 05:03:51 master0 astra-scheduler[38651]: I0617 05:03:51.862129   38651 eventhandlers.go:424] "Update event for scheduled pod" pod="astra-eval/eval-office-agent-654bd9764-bqnth"
Jun 17 05:03:51 master0 astra-scheduler[38651]: I0617 05:03:51.868404   38651 pod_binding.go:51] "Attempting to bind pod to node" pod="astra-eval/eval-live-moderation-5ff9cd648-7qs8p" node="worker1"
Jun 17 05:03:51 master0 astra-scheduler[38651]: I0617 05:03:51.874352   38651 schedule_one.go:337] "Successfully bound pod to node" pod="astra-eval/eval-live-moderation-5ff9cd648-7qs8p" node="worker1" evaluatedNodes=4 feasibleNodes=4
Jun 17 05:03:51 master0 astra-scheduler[38651]: I0617 05:03:51.874841   38651 eventhandlers.go:391] "Add event for scheduled pod" pod="astra-eval/eval-live-moderation-5ff9cd648-7qs8p"
Jun 17 05:03:51 master0 astra-scheduler[38651]: I0617 05:03:51.874861   38651 eventhandlers.go:352] "Delete event for unscheduled pod" pod="astra-eval/eval-live-moderation-5ff9cd648-7qs8p"
Jun 17 05:03:51 master0 astra-scheduler[38651]: I0617 05:03:51.895952   38651 eventhandlers.go:424] "Update event for scheduled pod" pod="astra-eval/eval-live-moderation-5ff9cd648-7qs8p"
Jun 17 05:03:52 master0 astra-scheduler[38651]: I0617 05:03:52.244285   38651 eventhandlers.go:424] "Update event for scheduled pod" pod="astra-eval/eval-office-agent-654bd9764-bqnth"
Jun 17 05:03:52 master0 astra-scheduler[38651]: I0617 05:03:52.276590   38651 eventhandlers.go:424] "Update event for scheduled pod" pod="astra-eval/eval-live-moderation-5ff9cd648-7qs8p"
Jun 17 05:03:52 master0 astra-scheduler[38651]: I0617 05:03:52.307223   38651 eventhandlers.go:424] "Update event for scheduled pod" pod="astra-eval/eval-office-agent-654bd9764-bqnth"
Jun 17 05:03:52 master0 astra-scheduler[38651]: I0617 05:03:52.333658   38651 eventhandlers.go:424] "Update event for scheduled pod" pod="astra-eval/eval-live-moderation-5ff9cd648-7qs8p"
Jun 17 05:03:54 master0 astra-scheduler[38651]: I0617 05:03:54.998476   38651 eventhandlers.go:424] "Update event for scheduled pod" pod="real-alert-registry/event-worker-image-puller-65b65544c7-nrp72"
Jun 17 05:04:04 master0 astra-scheduler[38651]: I0617 05:04:04.097716   38651 eventhandlers.go:424] "Update event for scheduled pod" pod="real-alert-service/notification-worker-missing-dependency-798b67d458-z92lr"
Jun 17 05:04:04 master0 astra-scheduler[38651]: I0617 05:04:04.811730   38651 eventhandlers.go:424] "Update event for scheduled pod" pod="real-alert-service/notification-worker-missing-dependency-798b67d458-z92lr"
Jun 17 05:04:06 master0 astra-scheduler[38651]: I0617 05:04:06.997841   38651 eventhandlers.go:424] "Update event for scheduled pod" pod="real-alert-crashloop/notification-worker-crashloop-56869f4d7-d88zw"
Jun 17 05:04:38 master0 astra-scheduler[38651]: I0617 05:04:38.730960   38651 reflector.go:991] "Watch close" reflector="pkg/mod/k8s.io/client-go@v0.35.0/tools/cache/reflector.go:289" type="*v1.VolumeAttachment" totalItems=10
Jun 17 05:04:41 master0 astra-scheduler[38651]: I0617 05:04:41.605916   38651 eventhandlers.go:83] "Update event for node" node="master0"
Jun 17 05:04:57 master0 astra-scheduler[38651]: I0617 05:04:57.003501   38651 eventhandlers.go:424] "Update event for scheduled pod" pod="real-alert-crashloop/auth-api-crashloop-597f8c568-97rwn"
Jun 17 05:05:01 master0 astra-scheduler[38651]: I0617 05:05:01.727457   38651 reflector.go:991] "Watch close" reflector="pkg/mod/k8s.io/client-go@v0.35.0/tools/cache/reflector.go:289" type="*v1.ResourceSlice" totalItems=10
Jun 17 05:05:07 master0 astra-scheduler[38651]: I0617 05:05:07.982844   38651 eventhandlers.go:424] "Update event for scheduled pod" pod="real-alert-service/billing-api-missing-dependency-57f59fc774-t2qlg"
Jun 17 05:05:08 master0 astra-scheduler[38651]: I0617 05:05:08.737753   38651 reflector.go:991] "Watch close" reflector="pkg/mod/k8s.io/client-go@v0.35.0/tools/cache/reflector.go:289" type="*v1.PersistentVolume" totalItems=11
Jun 17 05:05:08 master0 astra-scheduler[38651]: I0617 05:05:08.987410   38651 eventhandlers.go:424] "Update event for scheduled pod" pod="real-alert-service/billing-api-missing-dependency-57f59fc774-t2qlg"
Jun 17 05:05:10 master0 astra-scheduler[38651]: I0617 05:05:10.897575   38651 eventhandlers.go:424] "Update event for scheduled pod" pod="real-alert-registry/billing-image-puller-d99dfb7cf-w8tjc"
Jun 17 05:05:19 master0 astra-scheduler[38651]: I0617 05:05:19.316991   38651 eventhandlers.go:83] "Update event for node" node="worker0"
Jun 17 05:05:21 master0 astra-scheduler[38651]: I0617 05:05:21.769871   38651 reflector.go:991] "Watch close" reflector="pkg/mod/k8s.io/client-go@v0.35.0/tools/cache/reflector.go:289" type="*v1.CSIStorageCapacity" totalItems=9
Jun 17 05:05:22 master0 astra-scheduler[38651]: I0617 05:05:22.996523   38651 eventhandlers.go:424] "Update event for scheduled pod" pod="monitoring/job-dispatcher-694bcc8888-fptp7"
Jun 17 05:05:23 master0 astra-scheduler[38651]: I0617 05:05:23.778873   38651 reflector.go:991] "Watch close" reflector="pkg/mod/k8s.io/client-go@v0.35.0/tools/cache/reflector.go:289" type="*v1.ResourceClaim" totalItems=8
Jun 17 05:05:23 master0 astra-scheduler[38651]: I0617 05:05:23.899950   38651 eventhandlers.go:424] "Update event for scheduled pod" pod="real-alert-registry/billing-image-puller-d99dfb7cf-w8tjc"
Jun 17 05:05:30 master0 astra-scheduler[38651]: I0617 05:05:30.997635   38651 eventhandlers.go:424] "Update event for scheduled pod" pod="real-alert-service/notification-worker-missing-dependency-798b67d458-z92lr"
Jun 17 05:05:33 master0 astra-scheduler[38651]: I0617 05:05:33.613927   38651 eventhandlers.go:424] "Update event for scheduled pod" pod="astra-eval/eval-live-moderation-5ff9cd648-7qs8p"
Jun 17 05:05:33 master0 astra-scheduler[38651]: I0617 05:05:33.620757   38651 eventhandlers.go:424] "Update event for scheduled pod" pod="astra-eval/eval-office-agent-654bd9764-bqnth"
Jun 17 05:05:33 master0 astra-scheduler[38651]: I0617 05:05:33.635113   38651 eventhandlers.go:424] "Update event for scheduled pod" pod="astra-eval/eval-live-moderation-5ff9cd648-7qs8p"
Jun 17 05:05:33 master0 astra-scheduler[38651]: I0617 05:05:33.642149   38651 eventhandlers.go:424] "Update event for scheduled pod" pod="astra-eval/eval-office-agent-654bd9764-bqnth"
Jun 17 05:05:33 master0 astra-scheduler[38651]: I0617 05:05:33.739229   38651 eventhandlers.go:461] "Delete event for scheduled pod" pod="astra-eval/eval-live-moderation-5ff9cd648-7qs8p"
Jun 17 05:05:33 master0 astra-scheduler[38651]: I0617 05:05:33.751577   38651 eventhandlers.go:461] "Delete event for scheduled pod" pod="astra-eval/eval-office-agent-654bd9764-bqnth"
Jun 17 05:05:37 master0 astra-scheduler[38651]: I0617 05:05:37.999528   38651 eventhandlers.go:424] "Update event for scheduled pod" pod="monitoring/job-dispatcher-694bcc8888-fptp7"
Jun 17 05:05:38 master0 astra-scheduler[38651]: I0617 05:05:38.888412   38651 eventhandlers.go:233] "Add event for unscheduled pod" pod="astra-eval/eval-chat-service-65cf4f5c6-b8mth"
Jun 17 05:05:38 master0 astra-scheduler[38651]: I0617 05:05:38.888484   38651 schedule_one.go:83] "About to try and schedule pod" pod="astra-eval/eval-chat-service-65cf4f5c6-b8mth"
Jun 17 05:05:38 master0 astra-scheduler[38651]: I0617 05:05:38.888489   38651 schedule_one.go:99] "Attempting to schedule pod" pod="astra-eval/eval-chat-service-65cf4f5c6-b8mth"
Jun 17 05:05:38 master0 astra-scheduler[38651]: I0617 05:05:38.905380   38651 batch.go:90] "OpportunisticBatch no node hint available for pod" profile="astra-scheduler" pod="astra-eval/eval-chat-service-65cf4f5c6-b8mth" cycleCount=14
Jun 17 05:05:38 master0 astra-scheduler[38651]: I0617 05:05:38.908922   38651 eventhandlers.go:233] "Add event for unscheduled pod" pod="astra-eval/eval-batch-embedding-5fc67bd8cd-httmv"
Jun 17 05:05:38 master0 astra-scheduler[38651]: I0617 05:05:38.919617   38651 batch.go:118] "OpportunisticBatch set cycle state" pod="astra-eval/eval-chat-service-65cf4f5c6-b8mth" profile="astra-scheduler" cycleCount=14 hintedNode="" chosenNode="worker0"
Jun 17 05:05:38 master0 astra-scheduler[38651]: I0617 05:05:38.919645   38651 batch.go:168] "OpportunisticBatch found unusable state" pod="astra-eval/eval-chat-service-65cf4f5c6-b8mth" profile="astra-scheduler" cycleCount=14 reason="pod_not_batchable"
Jun 17 05:05:38 master0 astra-scheduler[38651]: I0617 05:05:38.927909   38651 schedule_one.go:83] "About to try and schedule pod" pod="astra-eval/eval-batch-embedding-5fc67bd8cd-httmv"
Jun 17 05:05:38 master0 astra-scheduler[38651]: I0617 05:05:38.927927   38651 schedule_one.go:99] "Attempting to schedule pod" pod="astra-eval/eval-batch-embedding-5fc67bd8cd-httmv"
Jun 17 05:05:38 master0 astra-scheduler[38651]: I0617 05:05:38.928187   38651 pod_binding.go:51] "Attempting to bind pod to node" pod="astra-eval/eval-chat-service-65cf4f5c6-b8mth" node="worker0"
Jun 17 05:05:38 master0 astra-scheduler[38651]: I0617 05:05:38.933956   38651 batch.go:90] "OpportunisticBatch no node hint available for pod" profile="astra-scheduler" pod="astra-eval/eval-batch-embedding-5fc67bd8cd-httmv" cycleCount=15
Jun 17 05:05:38 master0 astra-scheduler[38651]: I0617 05:05:38.935575   38651 schedule_one.go:337] "Successfully bound pod to node" pod="astra-eval/eval-chat-service-65cf4f5c6-b8mth" node="worker0" evaluatedNodes=4 feasibleNodes=4
Jun 17 05:05:38 master0 astra-scheduler[38651]: I0617 05:05:38.935767   38651 eventhandlers.go:391] "Add event for scheduled pod" pod="astra-eval/eval-chat-service-65cf4f5c6-b8mth"
Jun 17 05:05:38 master0 astra-scheduler[38651]: I0617 05:05:38.935786   38651 eventhandlers.go:352] "Delete event for unscheduled pod" pod="astra-eval/eval-chat-service-65cf4f5c6-b8mth"
Jun 17 05:05:38 master0 astra-scheduler[38651]: I0617 05:05:38.944275   38651 batch.go:118] "OpportunisticBatch set cycle state" pod="astra-eval/eval-batch-embedding-5fc67bd8cd-httmv" profile="astra-scheduler" cycleCount=15 hintedNode="" chosenNode="worker1"
Jun 17 05:05:38 master0 astra-scheduler[38651]: I0617 05:05:38.944302   38651 batch.go:168] "OpportunisticBatch found unusable state" pod="astra-eval/eval-batch-embedding-5fc67bd8cd-httmv" profile="astra-scheduler" cycleCount=15 reason="pod_not_batchable"
Jun 17 05:05:38 master0 astra-scheduler[38651]: I0617 05:05:38.952645   38651 pod_binding.go:51] "Attempting to bind pod to node" pod="astra-eval/eval-batch-embedding-5fc67bd8cd-httmv" node="worker1"
Jun 17 05:05:38 master0 astra-scheduler[38651]: I0617 05:05:38.958993   38651 eventhandlers.go:424] "Update event for scheduled pod" pod="astra-eval/eval-chat-service-65cf4f5c6-b8mth"
Jun 17 05:05:38 master0 astra-scheduler[38651]: I0617 05:05:38.961661   38651 eventhandlers.go:391] "Add event for scheduled pod" pod="astra-eval/eval-batch-embedding-5fc67bd8cd-httmv"
Jun 17 05:05:38 master0 astra-scheduler[38651]: I0617 05:05:38.961857   38651 eventhandlers.go:352] "Delete event for unscheduled pod" pod="astra-eval/eval-batch-embedding-5fc67bd8cd-httmv"
Jun 17 05:05:38 master0 astra-scheduler[38651]: I0617 05:05:38.962451   38651 schedule_one.go:337] "Successfully bound pod to node" pod="astra-eval/eval-batch-embedding-5fc67bd8cd-httmv" node="worker1" evaluatedNodes=4 feasibleNodes=4
Jun 17 05:05:38 master0 astra-scheduler[38651]: I0617 05:05:38.984349   38651 eventhandlers.go:424] "Update event for scheduled pod" pod="astra-eval/eval-batch-embedding-5fc67bd8cd-httmv"
Jun 17 05:05:39 master0 astra-scheduler[38651]: I0617 05:05:39.339948   38651 eventhandlers.go:424] "Update event for scheduled pod" pod="astra-eval/eval-chat-service-65cf4f5c6-b8mth"
Jun 17 05:05:39 master0 astra-scheduler[38651]: I0617 05:05:39.375325   38651 eventhandlers.go:424] "Update event for scheduled pod" pod="astra-eval/eval-batch-embedding-5fc67bd8cd-httmv"
Jun 17 05:05:39 master0 astra-scheduler[38651]: I0617 05:05:39.413353   38651 eventhandlers.go:424] "Update event for scheduled pod" pod="astra-eval/eval-chat-service-65cf4f5c6-b8mth"
Jun 17 05:05:39 master0 astra-scheduler[38651]: I0617 05:05:39.432659   38651 eventhandlers.go:424] "Update event for scheduled pod" pod="astra-eval/eval-batch-embedding-5fc67bd8cd-httmv"
Jun 17 05:05:46 master0 astra-scheduler[38651]: I0617 05:05:46.985701   38651 eventhandlers.go:424] "Update event for scheduled pod" pod="real-alert-service/checkout-api-missing-dependency-6ff5874d4b-bdvzp"
Jun 17 05:05:47 master0 astra-scheduler[38651]: I0617 05:05:47.086925   38651 eventhandlers.go:424] "Update event for scheduled pod" pod="real-alert-service/checkout-api-missing-dependency-6ff5874d4b-bdvzp"
Jun 17 05:06:28 master0 astra-scheduler[38651]: I0617 05:06:28.196712   38651 eventhandlers.go:424] "Update event for scheduled pod" pod="real-alert-crashloop/profile-api-crashloop-6455d4c94c-6j47k"
Jun 17 05:06:28 master0 astra-scheduler[38651]: I0617 05:06:28.744653   38651 reflector.go:991] "Watch close" reflector="pkg/mod/k8s.io/client-go@v0.35.0/tools/cache/reflector.go:289" type="*v1.Pod" totalItems=94
Jun 17 05:06:34 master0 astra-scheduler[38651]: I0617 05:06:34.789647   38651 reflector.go:991] "Watch close" reflector="pkg/mod/k8s.io/client-go@v0.35.0/tools/cache/reflector.go:289" type="*v1.PersistentVolumeClaim" totalItems=7
Jun 17 05:06:39 master0 astra-scheduler[38651]: I0617 05:06:39.902191   38651 eventhandlers.go:424] "Update event for scheduled pod" pod="real-alert-service/billing-api-missing-dependency-57f59fc774-t2qlg"
Jun 17 05:06:43 master0 astra-scheduler[38651]: I0617 05:06:43.746844   38651 reflector.go:991] "Watch close" reflector="pkg/mod/k8s.io/client-go@v0.35.0/tools/cache/reflector.go:289" type="*v1.ReplicationController" totalItems=8
Jun 17 05:07:05 master0 astra-scheduler[38651]: I0617 05:07:05.550891   38651 eventhandlers.go:424] "Update event for scheduled pod" pod="astra-eval/eval-chat-service-65cf4f5c6-b8mth"
Jun 17 05:07:05 master0 astra-scheduler[38651]: I0617 05:07:05.550957   38651 eventhandlers.go:424] "Update event for scheduled pod" pod="astra-eval/eval-batch-embedding-5fc67bd8cd-httmv"
Jun 17 05:07:05 master0 astra-scheduler[38651]: I0617 05:07:05.567950   38651 eventhandlers.go:424] "Update event for scheduled pod" pod="astra-eval/eval-chat-service-65cf4f5c6-b8mth"
Jun 17 05:07:05 master0 astra-scheduler[38651]: I0617 05:07:05.568474   38651 eventhandlers.go:424] "Update event for scheduled pod" pod="astra-eval/eval-batch-embedding-5fc67bd8cd-httmv"
Jun 17 05:07:05 master0 astra-scheduler[38651]: I0617 05:07:05.678351   38651 eventhandlers.go:461] "Delete event for scheduled pod" pod="astra-eval/eval-batch-embedding-5fc67bd8cd-httmv"
Jun 17 05:07:05 master0 astra-scheduler[38651]: I0617 05:07:05.683795   38651 eventhandlers.go:461] "Delete event for scheduled pod" pod="astra-eval/eval-chat-service-65cf4f5c6-b8mth"
Jun 17 05:07:09 master0 astra-scheduler[38651]: I0617 05:07:09.899385   38651 eventhandlers.go:424] "Update event for scheduled pod" pod="real-alert-service/checkout-api-missing-dependency-6ff5874d4b-bdvzp"
Jun 17 05:07:10 master0 astra-scheduler[38651]: I0617 05:07:10.752298   38651 eventhandlers.go:233] "Add event for unscheduled pod" pod="astra-eval/eval-risk-sensitive-chat-7d45bb7568-js7lr"
Jun 17 05:07:10 master0 astra-scheduler[38651]: I0617 05:07:10.752356   38651 schedule_one.go:83] "About to try and schedule pod" pod="astra-eval/eval-risk-sensitive-chat-7d45bb7568-js7lr"
Jun 17 05:07:10 master0 astra-scheduler[38651]: I0617 05:07:10.752361   38651 schedule_one.go:99] "Attempting to schedule pod" pod="astra-eval/eval-risk-sensitive-chat-7d45bb7568-js7lr"
Jun 17 05:07:10 master0 astra-scheduler[38651]: I0617 05:07:10.755596   38651 batch.go:90] "OpportunisticBatch no node hint available for pod" profile="astra-scheduler" pod="astra-eval/eval-risk-sensitive-chat-7d45bb7568-js7lr" cycleCount=16
Jun 17 05:07:10 master0 astra-scheduler[38651]: I0617 05:07:10.767857   38651 batch.go:118] "OpportunisticBatch set cycle state" pod="astra-eval/eval-risk-sensitive-chat-7d45bb7568-js7lr" profile="astra-scheduler" cycleCount=16 hintedNode="" chosenNode="master0"
Jun 17 05:07:10 master0 astra-scheduler[38651]: I0617 05:07:10.767912   38651 batch.go:168] "OpportunisticBatch found unusable state" pod="astra-eval/eval-risk-sensitive-chat-7d45bb7568-js7lr" profile="astra-scheduler" cycleCount=16 reason="pod_not_batchable"
Jun 17 05:07:10 master0 astra-scheduler[38651]: I0617 05:07:10.785678   38651 pod_binding.go:51] "Attempting to bind pod to node" pod="astra-eval/eval-risk-sensitive-chat-7d45bb7568-js7lr" node="master0"
Jun 17 05:07:10 master0 astra-scheduler[38651]: I0617 05:07:10.790197   38651 schedule_one.go:337] "Successfully bound pod to node" pod="astra-eval/eval-risk-sensitive-chat-7d45bb7568-js7lr" node="master0" evaluatedNodes=4 feasibleNodes=4
Jun 17 05:07:10 master0 astra-scheduler[38651]: I0617 05:07:10.790785   38651 eventhandlers.go:391] "Add event for scheduled pod" pod="astra-eval/eval-risk-sensitive-chat-7d45bb7568-js7lr"
Jun 17 05:07:10 master0 astra-scheduler[38651]: I0617 05:07:10.790821   38651 eventhandlers.go:352] "Delete event for unscheduled pod" pod="astra-eval/eval-risk-sensitive-chat-7d45bb7568-js7lr"
Jun 17 05:07:10 master0 astra-scheduler[38651]: I0617 05:07:10.801985   38651 eventhandlers.go:424] "Update event for scheduled pod" pod="astra-eval/eval-risk-sensitive-chat-7d45bb7568-js7lr"
Jun 17 05:07:11 master0 astra-scheduler[38651]: I0617 05:07:11.180980   38651 eventhandlers.go:424] "Update event for scheduled pod" pod="astra-eval/eval-risk-sensitive-chat-7d45bb7568-js7lr"
Jun 17 05:07:11 master0 astra-scheduler[38651]: I0617 05:07:11.231000   38651 eventhandlers.go:424] "Update event for scheduled pod" pod="astra-eval/eval-risk-sensitive-chat-7d45bb7568-js7lr"
Jun 17 05:07:11 master0 astra-scheduler[38651]: I0617 05:07:11.732974   38651 reflector.go:991] "Watch close" reflector="pkg/mod/k8s.io/client-go@v0.35.0/tools/cache/reflector.go:289" type="*v1.ReplicaSet" totalItems=39
Jun 17 05:07:22 master0 astra-scheduler[38651]: I0617 05:07:22.728724   38651 reflector.go:991] "Watch close" reflector="pkg/mod/k8s.io/client-go@v0.35.0/tools/cache/reflector.go:289" type="*v1.DeviceClass" totalItems=10
Jun 17 05:07:23 master0 astra-scheduler[38651]: I0617 05:07:23.779633   38651 reflector.go:991] "Watch close" reflector="pkg/mod/k8s.io/client-go@v0.35.0/tools/cache/reflector.go:289" type="*v1.Node" totalItems=10
Jun 17 05:07:25 master0 astra-scheduler[38651]: I0617 05:07:25.745809   38651 reflector.go:991] "Watch close" reflector="pkg/mod/k8s.io/client-go@v0.35.0/tools/cache/reflector.go:289" type="*v1.StatefulSet" totalItems=7
Jun 17 05:07:29 master0 astra-scheduler[38651]: I0617 05:07:29.899541   38651 eventhandlers.go:424] "Update event for scheduled pod" pod="real-alert-crashloop/profile-api-crashloop-6455d4c94c-6j47k"
Jun 17 05:07:31 master0 astra-scheduler[38651]: I0617 05:07:31.741465   38651 reflector.go:991] "Watch close" reflector="pkg/mod/k8s.io/client-go@v0.35.0/tools/cache/reflector.go:289" type="*v1.CSIDriver" totalItems=8
Jun 17 05:07:47 master0 astra-scheduler[38651]: I0617 05:07:47.740316   38651 reflector.go:991] "Watch close" reflector="pkg/mod/k8s.io/client-go@v0.35.0/tools/cache/reflector.go:289" type="*v1.CSINode" totalItems=11
Jun 17 05:08:08 master0 astra-scheduler[38651]: I0617 05:08:08.500836   38651 eventhandlers.go:424] "Update event for scheduled pod" pod="real-alert-crashloop/notification-worker-crashloop-56869f4d7-d88zw"
Jun 17 05:08:17 master0 astra-scheduler[38651]: I0617 05:08:17.744344   38651 reflector.go:991] "Watch close" reflector="pkg/mod/k8s.io/client-go@v0.35.0/tools/cache/reflector.go:289" type="*v1.PodDisruptionBudget" totalItems=8
Jun 17 05:08:25 master0 astra-scheduler[38651]: I0617 05:08:25.998197   38651 eventhandlers.go:424] "Update event for scheduled pod" pod="real-alert-registry/checkout-image-puller-6644fc5fd-xr9vn"
Jun 17 05:08:36 master0 astra-scheduler[38651]: I0617 05:08:36.402318   38651 eventhandlers.go:83] "Update event for node" node="master1"
Jun 17 05:08:38 master0 astra-scheduler[38651]: I0617 05:08:38.069218   38651 eventhandlers.go:83] "Update event for node" node="worker1"
Jun 17 05:08:38 master0 astra-scheduler[38651]: I0617 05:08:38.999182   38651 eventhandlers.go:424] "Update event for scheduled pod" pod="real-alert-registry/checkout-image-puller-6644fc5fd-xr9vn"
Jun 17 05:08:40 master0 astra-scheduler[38651]: I0617 05:08:40.998818   38651 eventhandlers.go:424] "Update event for scheduled pod" pod="real-alert-registry/event-worker-image-puller-65b65544c7-nrp72"
Jun 17 05:08:47 master0 astra-scheduler[38651]: I0617 05:08:47.368760   38651 eventhandlers.go:424] "Update event for scheduled pod" pod="astra-eval/eval-risk-sensitive-chat-7d45bb7568-js7lr"
Jun 17 05:08:47 master0 astra-scheduler[38651]: I0617 05:08:47.379850   38651 eventhandlers.go:424] "Update event for scheduled pod" pod="astra-eval/eval-risk-sensitive-chat-7d45bb7568-js7lr"
Jun 17 05:08:47 master0 astra-scheduler[38651]: I0617 05:08:47.479994   38651 eventhandlers.go:461] "Delete event for scheduled pod" pod="astra-eval/eval-risk-sensitive-chat-7d45bb7568-js7lr"
Jun 17 05:08:51 master0 astra-scheduler[38651]: I0617 05:08:51.997545   38651 eventhandlers.go:424] "Update event for scheduled pod" pod="real-alert-registry/event-worker-image-puller-65b65544c7-nrp72"
Jun 17 05:08:52 master0 astra-scheduler[38651]: I0617 05:08:52.536973   38651 eventhandlers.go:233] "Add event for unscheduled pod" pod="astra-eval/eval-decode-chat-7c58f7b588-tcxlk"
Jun 17 05:08:52 master0 astra-scheduler[38651]: I0617 05:08:52.537103   38651 schedule_one.go:83] "About to try and schedule pod" pod="astra-eval/eval-decode-chat-7c58f7b588-tcxlk"
Jun 17 05:08:52 master0 astra-scheduler[38651]: I0617 05:08:52.537114   38651 schedule_one.go:99] "Attempting to schedule pod" pod="astra-eval/eval-decode-chat-7c58f7b588-tcxlk"
Jun 17 05:08:52 master0 astra-scheduler[38651]: I0617 05:08:52.540954   38651 batch.go:90] "OpportunisticBatch no node hint available for pod" profile="astra-scheduler" pod="astra-eval/eval-decode-chat-7c58f7b588-tcxlk" cycleCount=17
Jun 17 05:08:52 master0 astra-scheduler[38651]: I0617 05:08:52.544137   38651 eventhandlers.go:233] "Add event for unscheduled pod" pod="astra-eval/eval-prefill-embedding-6b879fb958-wl88g"
Jun 17 05:08:52 master0 astra-scheduler[38651]: I0617 05:08:52.551876   38651 batch.go:118] "OpportunisticBatch set cycle state" pod="astra-eval/eval-decode-chat-7c58f7b588-tcxlk" profile="astra-scheduler" cycleCount=17 hintedNode="" chosenNode="worker0"
Jun 17 05:08:52 master0 astra-scheduler[38651]: I0617 05:08:52.551906   38651 batch.go:168] "OpportunisticBatch found unusable state" pod="astra-eval/eval-decode-chat-7c58f7b588-tcxlk" profile="astra-scheduler" cycleCount=17 reason="pod_not_batchable"
Jun 17 05:08:52 master0 astra-scheduler[38651]: I0617 05:08:52.560937   38651 eventhandlers.go:233] "Add event for unscheduled pod" pod="astra-eval/eval-kv-agent-74f59b67b4-j5db8"
Jun 17 05:08:52 master0 astra-scheduler[38651]: I0617 05:08:52.565768   38651 schedule_one.go:83] "About to try and schedule pod" pod="astra-eval/eval-prefill-embedding-6b879fb958-wl88g"
Jun 17 05:08:52 master0 astra-scheduler[38651]: I0617 05:08:52.565791   38651 schedule_one.go:99] "Attempting to schedule pod" pod="astra-eval/eval-prefill-embedding-6b879fb958-wl88g"
Jun 17 05:08:52 master0 astra-scheduler[38651]: I0617 05:08:52.565973   38651 pod_binding.go:51] "Attempting to bind pod to node" pod="astra-eval/eval-decode-chat-7c58f7b588-tcxlk" node="worker0"
Jun 17 05:08:52 master0 astra-scheduler[38651]: I0617 05:08:52.570532   38651 batch.go:90] "OpportunisticBatch no node hint available for pod" profile="astra-scheduler" pod="astra-eval/eval-prefill-embedding-6b879fb958-wl88g" cycleCount=18
Jun 17 05:08:52 master0 astra-scheduler[38651]: I0617 05:08:52.573685   38651 eventhandlers.go:391] "Add event for scheduled pod" pod="astra-eval/eval-decode-chat-7c58f7b588-tcxlk"
Jun 17 05:08:52 master0 astra-scheduler[38651]: I0617 05:08:52.573741   38651 eventhandlers.go:352] "Delete event for unscheduled pod" pod="astra-eval/eval-decode-chat-7c58f7b588-tcxlk"
Jun 17 05:08:52 master0 astra-scheduler[38651]: I0617 05:08:52.575968   38651 schedule_one.go:337] "Successfully bound pod to node" pod="astra-eval/eval-decode-chat-7c58f7b588-tcxlk" node="worker0" evaluatedNodes=4 feasibleNodes=4
Jun 17 05:08:52 master0 astra-scheduler[38651]: I0617 05:08:52.576491   38651 batch.go:118] "OpportunisticBatch set cycle state" pod="astra-eval/eval-prefill-embedding-6b879fb958-wl88g" profile="astra-scheduler" cycleCount=18 hintedNode="" chosenNode="worker1"
Jun 17 05:08:52 master0 astra-scheduler[38651]: I0617 05:08:52.576507   38651 batch.go:168] "OpportunisticBatch found unusable state" pod="astra-eval/eval-prefill-embedding-6b879fb958-wl88g" profile="astra-scheduler" cycleCount=18 reason="pod_not_batchable"
Jun 17 05:08:52 master0 astra-scheduler[38651]: I0617 05:08:52.597696   38651 schedule_one.go:83] "About to try and schedule pod" pod="astra-eval/eval-kv-agent-74f59b67b4-j5db8"
Jun 17 05:08:52 master0 astra-scheduler[38651]: I0617 05:08:52.597778   38651 schedule_one.go:99] "Attempting to schedule pod" pod="astra-eval/eval-kv-agent-74f59b67b4-j5db8"
Jun 17 05:08:52 master0 astra-scheduler[38651]: I0617 05:08:52.597883   38651 pod_binding.go:51] "Attempting to bind pod to node" pod="astra-eval/eval-prefill-embedding-6b879fb958-wl88g" node="worker1"
Jun 17 05:08:52 master0 astra-scheduler[38651]: I0617 05:08:52.597713   38651 eventhandlers.go:424] "Update event for scheduled pod" pod="astra-eval/eval-decode-chat-7c58f7b588-tcxlk"
Jun 17 05:08:52 master0 astra-scheduler[38651]: I0617 05:08:52.602588   38651 eventhandlers.go:391] "Add event for scheduled pod" pod="astra-eval/eval-prefill-embedding-6b879fb958-wl88g"
Jun 17 05:08:52 master0 astra-scheduler[38651]: I0617 05:08:52.602637   38651 eventhandlers.go:352] "Delete event for unscheduled pod" pod="astra-eval/eval-prefill-embedding-6b879fb958-wl88g"
Jun 17 05:08:52 master0 astra-scheduler[38651]: I0617 05:08:52.602713   38651 schedule_one.go:337] "Successfully bound pod to node" pod="astra-eval/eval-prefill-embedding-6b879fb958-wl88g" node="worker1" evaluatedNodes=4 feasibleNodes=4
Jun 17 05:08:52 master0 astra-scheduler[38651]: I0617 05:08:52.602913   38651 batch.go:90] "OpportunisticBatch no node hint available for pod" profile="astra-scheduler" pod="astra-eval/eval-kv-agent-74f59b67b4-j5db8" cycleCount=19
Jun 17 05:08:52 master0 astra-scheduler[38651]: I0617 05:08:52.612445   38651 batch.go:118] "OpportunisticBatch set cycle state" pod="astra-eval/eval-kv-agent-74f59b67b4-j5db8" profile="astra-scheduler" cycleCount=19 hintedNode="" chosenNode="worker0"
Jun 17 05:08:52 master0 astra-scheduler[38651]: I0617 05:08:52.612540   38651 batch.go:168] "OpportunisticBatch found unusable state" pod="astra-eval/eval-kv-agent-74f59b67b4-j5db8" profile="astra-scheduler" cycleCount=19 reason="pod_not_batchable"
Jun 17 05:08:52 master0 astra-scheduler[38651]: I0617 05:08:52.622454   38651 eventhandlers.go:424] "Update event for scheduled pod" pod="astra-eval/eval-prefill-embedding-6b879fb958-wl88g"
Jun 17 05:08:52 master0 astra-scheduler[38651]: I0617 05:08:52.624339   38651 pod_binding.go:51] "Attempting to bind pod to node" pod="astra-eval/eval-kv-agent-74f59b67b4-j5db8" node="worker0"
Jun 17 05:08:52 master0 astra-scheduler[38651]: I0617 05:08:52.631424   38651 eventhandlers.go:391] "Add event for scheduled pod" pod="astra-eval/eval-kv-agent-74f59b67b4-j5db8"
Jun 17 05:08:52 master0 astra-scheduler[38651]: I0617 05:08:52.631470   38651 eventhandlers.go:352] "Delete event for unscheduled pod" pod="astra-eval/eval-kv-agent-74f59b67b4-j5db8"
Jun 17 05:08:52 master0 astra-scheduler[38651]: I0617 05:08:52.632922   38651 schedule_one.go:337] "Successfully bound pod to node" pod="astra-eval/eval-kv-agent-74f59b67b4-j5db8" node="worker0" evaluatedNodes=4 feasibleNodes=4
Jun 17 05:08:52 master0 astra-scheduler[38651]: I0617 05:08:52.654355   38651 eventhandlers.go:424] "Update event for scheduled pod" pod="astra-eval/eval-kv-agent-74f59b67b4-j5db8"
Jun 17 05:08:52 master0 astra-scheduler[38651]: I0617 05:08:52.982785   38651 eventhandlers.go:424] "Update event for scheduled pod" pod="astra-eval/eval-decode-chat-7c58f7b588-tcxlk"
Jun 17 05:08:53 master0 astra-scheduler[38651]: I0617 05:08:53.011709   38651 eventhandlers.go:424] "Update event for scheduled pod" pod="astra-eval/eval-prefill-embedding-6b879fb958-wl88g"
Jun 17 05:08:53 master0 astra-scheduler[38651]: I0617 05:08:53.061793   38651 eventhandlers.go:424] "Update event for scheduled pod" pod="astra-eval/eval-decode-chat-7c58f7b588-tcxlk"
Jun 17 05:08:53 master0 astra-scheduler[38651]: I0617 05:08:53.071735   38651 eventhandlers.go:424] "Update event for scheduled pod" pod="astra-eval/eval-prefill-embedding-6b879fb958-wl88g"
Jun 17 05:08:53 master0 astra-scheduler[38651]: I0617 05:08:53.073541   38651 eventhandlers.go:424] "Update event for scheduled pod" pod="astra-eval/eval-kv-agent-74f59b67b4-j5db8"
Jun 17 05:08:53 master0 astra-scheduler[38651]: I0617 05:08:53.117619   38651 eventhandlers.go:424] "Update event for scheduled pod" pod="astra-eval/eval-kv-agent-74f59b67b4-j5db8"
Jun 17 05:08:53 master0 astra-scheduler[38651]: I0617 05:08:53.617314   38651 eventhandlers.go:424] "Update event for scheduled pod" pod="real-alert-crashloop/auth-api-crashloop-597f8c568-97rwn"
Jun 17 05:09:15 master0 astra-scheduler[38651]: I0617 05:09:15.085325   38651 eventhandlers.go:424] "Update event for scheduled pod" pod="real-alert-service/notification-worker-missing-dependency-798b67d458-z92lr"
Jun 17 05:09:15 master0 astra-scheduler[38651]: I0617 05:09:15.674185   38651 eventhandlers.go:424] "Update event for scheduled pod" pod="real-alert-service/notification-worker-missing-dependency-798b67d458-z92lr"
Jun 17 05:09:20 master0 astra-scheduler[38651]: I0617 05:09:20.724860   38651 reflector.go:991] "Watch close" reflector="pkg/mod/k8s.io/client-go@v0.35.0/tools/cache/reflector.go:289" type="*v1.StorageClass" totalItems=8
Jun 17 05:09:28 master0 astra-scheduler[38651]: I0617 05:09:28.065348   38651 eventhandlers.go:424] "Update event for scheduled pod" pod="astra-eval/eval-prefill-embedding-6b879fb958-wl88g"
Jun 17 05:09:28 master0 astra-scheduler[38651]: I0617 05:09:28.066475   38651 eventhandlers.go:424] "Update event for scheduled pod" pod="astra-eval/eval-decode-chat-7c58f7b588-tcxlk"
Jun 17 05:09:28 master0 astra-scheduler[38651]: I0617 05:09:28.080717   38651 eventhandlers.go:424] "Update event for scheduled pod" pod="astra-eval/eval-kv-agent-74f59b67b4-j5db8"
Jun 17 05:09:28 master0 astra-scheduler[38651]: I0617 05:09:28.084397   38651 eventhandlers.go:424] "Update event for scheduled pod" pod="astra-eval/eval-prefill-embedding-6b879fb958-wl88g"
Jun 17 05:09:28 master0 astra-scheduler[38651]: I0617 05:09:28.091326   38651 eventhandlers.go:424] "Update event for scheduled pod" pod="astra-eval/eval-decode-chat-7c58f7b588-tcxlk"
Jun 17 05:09:28 master0 astra-scheduler[38651]: I0617 05:09:28.106336   38651 eventhandlers.go:424] "Update event for scheduled pod" pod="astra-eval/eval-kv-agent-74f59b67b4-j5db8"
Jun 17 05:09:28 master0 astra-scheduler[38651]: I0617 05:09:28.195599   38651 eventhandlers.go:461] "Delete event for scheduled pod" pod="astra-eval/eval-prefill-embedding-6b879fb958-wl88g"
Jun 17 05:09:28 master0 astra-scheduler[38651]: I0617 05:09:28.208123   38651 eventhandlers.go:461] "Delete event for scheduled pod" pod="astra-eval/eval-decode-chat-7c58f7b588-tcxlk"
Jun 17 05:09:28 master0 astra-scheduler[38651]: I0617 05:09:28.222830   38651 eventhandlers.go:461] "Delete event for scheduled pod" pod="astra-eval/eval-kv-agent-74f59b67b4-j5db8"
Jun 17 05:09:33 master0 astra-scheduler[38651]: I0617 05:09:33.410590   38651 eventhandlers.go:233] "Add event for unscheduled pod" pod="astra-eval/eval-live-moderation-5ff9cd648-z9fjj"
Jun 17 05:09:33 master0 astra-scheduler[38651]: I0617 05:09:33.410652   38651 schedule_one.go:83] "About to try and schedule pod" pod="astra-eval/eval-live-moderation-5ff9cd648-z9fjj"
Jun 17 05:09:33 master0 astra-scheduler[38651]: I0617 05:09:33.410657   38651 schedule_one.go:99] "Attempting to schedule pod" pod="astra-eval/eval-live-moderation-5ff9cd648-z9fjj"
Jun 17 05:09:33 master0 astra-scheduler[38651]: I0617 05:09:33.414729   38651 batch.go:90] "OpportunisticBatch no node hint available for pod" profile="astra-scheduler" pod="astra-eval/eval-live-moderation-5ff9cd648-z9fjj" cycleCount=20
Jun 17 05:09:33 master0 astra-scheduler[38651]: I0617 05:09:33.421832   38651 eventhandlers.go:233] "Add event for unscheduled pod" pod="astra-eval/eval-office-agent-654bd9764-4l5hf"
Jun 17 05:09:33 master0 astra-scheduler[38651]: I0617 05:09:33.423551   38651 batch.go:118] "OpportunisticBatch set cycle state" pod="astra-eval/eval-live-moderation-5ff9cd648-z9fjj" profile="astra-scheduler" cycleCount=20 hintedNode="" chosenNode="master0"
Jun 17 05:09:33 master0 astra-scheduler[38651]: I0617 05:09:33.423579   38651 batch.go:168] "OpportunisticBatch found unusable state" pod="astra-eval/eval-live-moderation-5ff9cd648-z9fjj" profile="astra-scheduler" cycleCount=20 reason="pod_not_batchable"
Jun 17 05:09:33 master0 astra-scheduler[38651]: I0617 05:09:33.439754   38651 schedule_one.go:83] "About to try and schedule pod" pod="astra-eval/eval-office-agent-654bd9764-4l5hf"
Jun 17 05:09:33 master0 astra-scheduler[38651]: I0617 05:09:33.439797   38651 schedule_one.go:99] "Attempting to schedule pod" pod="astra-eval/eval-office-agent-654bd9764-4l5hf"
Jun 17 05:09:33 master0 astra-scheduler[38651]: I0617 05:09:33.439944   38651 pod_binding.go:51] "Attempting to bind pod to node" pod="astra-eval/eval-live-moderation-5ff9cd648-z9fjj" node="master0"
Jun 17 05:09:33 master0 astra-scheduler[38651]: I0617 05:09:33.444593   38651 batch.go:90] "OpportunisticBatch no node hint available for pod" profile="astra-scheduler" pod="astra-eval/eval-office-agent-654bd9764-4l5hf" cycleCount=21
Jun 17 05:09:33 master0 astra-scheduler[38651]: I0617 05:09:33.445104   38651 schedule_one.go:337] "Successfully bound pod to node" pod="astra-eval/eval-live-moderation-5ff9cd648-z9fjj" node="master0" evaluatedNodes=4 feasibleNodes=4
Jun 17 05:09:33 master0 astra-scheduler[38651]: I0617 05:09:33.445301   38651 eventhandlers.go:391] "Add event for scheduled pod" pod="astra-eval/eval-live-moderation-5ff9cd648-z9fjj"
Jun 17 05:09:33 master0 astra-scheduler[38651]: I0617 05:09:33.445335   38651 eventhandlers.go:352] "Delete event for unscheduled pod" pod="astra-eval/eval-live-moderation-5ff9cd648-z9fjj"
Jun 17 05:09:33 master0 astra-scheduler[38651]: I0617 05:09:33.455737   38651 batch.go:118] "OpportunisticBatch set cycle state" pod="astra-eval/eval-office-agent-654bd9764-4l5hf" profile="astra-scheduler" cycleCount=21 hintedNode="" chosenNode="worker1"
Jun 17 05:09:33 master0 astra-scheduler[38651]: I0617 05:09:33.455765   38651 batch.go:168] "OpportunisticBatch found unusable state" pod="astra-eval/eval-office-agent-654bd9764-4l5hf" profile="astra-scheduler" cycleCount=21 reason="pod_not_batchable"
Jun 17 05:09:33 master0 astra-scheduler[38651]: I0617 05:09:33.461474   38651 eventhandlers.go:424] "Update event for scheduled pod" pod="astra-eval/eval-live-moderation-5ff9cd648-z9fjj"
Jun 17 05:09:33 master0 astra-scheduler[38651]: I0617 05:09:33.470331   38651 pod_binding.go:51] "Attempting to bind pod to node" pod="astra-eval/eval-office-agent-654bd9764-4l5hf" node="worker1"
Jun 17 05:09:33 master0 astra-scheduler[38651]: I0617 05:09:33.475903   38651 eventhandlers.go:391] "Add event for scheduled pod" pod="astra-eval/eval-office-agent-654bd9764-4l5hf"
Jun 17 05:09:33 master0 astra-scheduler[38651]: I0617 05:09:33.475949   38651 eventhandlers.go:352] "Delete event for unscheduled pod" pod="astra-eval/eval-office-agent-654bd9764-4l5hf"
Jun 17 05:09:33 master0 astra-scheduler[38651]: I0617 05:09:33.476002   38651 schedule_one.go:337] "Successfully bound pod to node" pod="astra-eval/eval-office-agent-654bd9764-4l5hf" node="worker1" evaluatedNodes=4 feasibleNodes=4
Jun 17 05:09:33 master0 astra-scheduler[38651]: I0617 05:09:33.493503   38651 eventhandlers.go:424] "Update event for scheduled pod" pod="astra-eval/eval-office-agent-654bd9764-4l5hf"
Jun 17 05:09:33 master0 astra-scheduler[38651]: I0617 05:09:33.852829   38651 eventhandlers.go:424] "Update event for scheduled pod" pod="astra-eval/eval-live-moderation-5ff9cd648-z9fjj"
Jun 17 05:09:33 master0 astra-scheduler[38651]: I0617 05:09:33.885726   38651 eventhandlers.go:424] "Update event for scheduled pod" pod="astra-eval/eval-office-agent-654bd9764-4l5hf"
Jun 17 05:09:33 master0 astra-scheduler[38651]: I0617 05:09:33.921431   38651 eventhandlers.go:424] "Update event for scheduled pod" pod="astra-eval/eval-live-moderation-5ff9cd648-z9fjj"
Jun 17 05:09:33 master0 astra-scheduler[38651]: I0617 05:09:33.944210   38651 eventhandlers.go:424] "Update event for scheduled pod" pod="astra-eval/eval-office-agent-654bd9764-4l5hf"
Jun 17 05:09:33 master0 astra-scheduler[38651]: I0617 05:09:33.997937   38651 eventhandlers.go:424] "Update event for scheduled pod" pod="real-alert-crashloop/notification-worker-crashloop-56869f4d7-d88zw"
Jun 17 05:09:47 master0 astra-scheduler[38651]: I0617 05:09:47.333285   38651 eventhandlers.go:83] "Update event for node" node="master0"
